<?xml version="1.0" ?>
<!-- =================================================================================== -->
<!-- |    This document was autogenerated by xacro from rs_m90e7.urdf.xacro            | -->
<!-- |    EDITING THIS FILE BY HAND IS NOT RECOMMENDED                                 | -->
<!-- =================================================================================== -->
<robot name="rs_m90e7">
  <!-- ======================================================== -->
  <!-- robot link -->
  <!-- ======================================================== -->
  <link name="base_link">
    <inertial>
      <origin rpy="0 0 0" xyz="0.00000 0.00000 0.00000"/>
      <mass value="1.0"/>
      <inertia ixx=" 0.001000" ixy=" 0.000000" ixz=" 0.000000" iyy=" 0.001000" iyz=" 0.000000" izz=" 0.001000"/>
    </inertial>
    <visual>
      <origin rpy="0 0 0" xyz="0 0 0"/>
      <geometry>
        <mesh filename="package://rs_m90e7_description/meshes/base_link.dae"/>
      </geometry>
      <material name="">
        <color rgba="1 1 1 1"/>
      </material>
    </visual>
    <collision>
      <origin rpy="0 0 0" xyz="0 0 0"/>
      <geometry>
        <mesh filename="package://rs_m90e7_description/meshes/base_link.stl"/>
      </geometry>
    </collision>
  </link>
  <link name="link1">
    <inertial>
      <origin rpy="0 0 0" xyz="-0.007155             0.074751             0.000996"/>
      <mass value="5.600"/>
      <inertia ixx=" 0.019807" ixy=" 0.000000" ixz=" 0.000000" iyy=" 0.013098" iyz=" 0.000000" izz=" 0.020563"/>
    </inertial>
    <visual>
      <origin rpy="0 0 0" xyz="0 0 0"/>
      <geometry>
        <mesh filename="package://rs_m90e7_description/meshes/link1.dae"/>
      </geometry>
      <material name="">
        <color rgba="1 1 1 1"/>
      </material>
    </visual>
    <collision>
      <origin rpy="0 0 0" xyz="0 0 0"/>
      <geometry>
        <mesh filename="package://rs_m90e7_description/meshes/link1.stl"/>
      </geometry>
    </collision>
  </link>
  <link name="link2">
    <inertial>
      <origin rpy="0 0 0" xyz="-0.215018             0.080988             0.000000"/>
      <mass value="13.799"/>
      <inertia ixx=" 0.041621" ixy=" 0.000000" ixz=" 0.000000" iyy=" 0.542754" iyz=" 0.000000" izz=" 0.555726"/>
    </inertial>
    <visual>
      <origin rpy="0 0 0" xyz="0 0 0"/>
      <geometry>
        <mesh filename="package://rs_m90e7_description/meshes/link2.dae"/>
      </geometry>
      <material name="">
        <color rgba="1 1 1 1"/>
      </material>
    </visual>
    <collision>
      <origin rpy="0 0 0" xyz="0 0 0"/>
      <geometry>
        <mesh filename="package://rs_m90e7_description/meshes/link2.stl"/>
      </geometry>
    </collision>
  </link>
  <link name="link3">
    <inertial>
      <origin rpy="0 0 0" xyz="-0.256997             0.061315            -0.000055"/>
      <mass value="4.137"/>
      <inertia ixx=" 0.007112" ixy=" 0.000000" ixz=" 0.000000" iyy=" 0.122290" iyz=" 0.000000" izz=" 0.124242"/>
    </inertial>
    <visual>
      <origin rpy="0 0 0" xyz="0 0 0"/>
      <geometry>
        <mesh filename="package://rs_m90e7_description/meshes/link3.dae"/>
      </geometry>
      <material name="">
        <color rgba="1 1 1 1"/>
      </material>
    </visual>
    <collision>
      <origin rpy="0 0 0" xyz="0 0 0"/>
      <geometry>
        <mesh filename="package://rs_m90e7_description/meshes/link3.stl"/>
      </geometry>
    </collision>
  </link>
  <link name="link4">
    <inertial>
      <origin rpy="0 0 0" xyz=" 0.026648             0.059889             0.000116"/>
      <mass value="2.000"/>
      <inertia ixx=" 0.002061" ixy=" 0.000000" ixz=" 0.000000" iyy=" 0.003868" iyz=" 0.000000" izz=" 0.003992"/>
    </inertial>
    <visual>
      <origin rpy="0 0 0" xyz="0 0 0"/>
      <geometry>
        <mesh filename="package://rs_m90e7_description/meshes/link4.dae"/>
      </geometry>
      <material name="">
        <color rgba="1 1 1 1"/>
      </material>
    </visual>
    <collision>
      <origin rpy="0 0 0" xyz="0 0 0"/>
      <geometry>
        <mesh filename="package://rs_m90e7_description/meshes/link4.stl"/>
      </geometry>
    </collision>
  </link>
  <link name="link5">
    <inertial>
      <origin rpy="0 0 0" xyz=" 0.026648             0.053986             0.000116"/>
      <mass value="2.000"/>
      <inertia ixx=" 0.002061" ixy=" 0.000000" ixz=" 0.000000" iyy=" 0.003868" iyz=" 0.000000" izz=" 0.003992"/>
    </inertial>
    <visual>
      <origin rpy="0 0 0" xyz="0 0 0"/>
      <geometry>
        <mesh filename="package://rs_m90e7_description/meshes/link5.dae"/>
      </geometry>
      <material name="">
        <color rgba="1 1 1 1"/>
      </material>
    </visual>
    <collision>
      <origin rpy="0 0 0" xyz="0 0 0"/>
      <geometry>
        <mesh filename="package://rs_m90e7_description/meshes/link5.stl"/>
      </geometry>
    </collision>
  </link>
  <link name="link6">
    <inertial>
      <origin rpy="0 0 0" xyz="-0.002215             0.037943            -0.000790"/>
      <mass value="0.395"/>
      <inertia ixx=" 0.000411" ixy=" 0.000000" ixz=" 0.000000" iyy=" 0.000483" iyz=" 0.000000" izz=" 0.000429"/>
    </inertial>
    <visual>
      <origin rpy="0 0 0" xyz="0 0 0"/>
      <geometry>
        <mesh filename="package://rs_m90e7_description/meshes/link6.dae"/>
      </geometry>
      <material name="">
        <color rgba="1 1 1 1"/>
      </material>
    </visual>
    <collision>
      <origin rpy="0 0 0" xyz="0 0 0"/>
      <geometry>
        <mesh filename="package://rs_m90e7_description/meshes/link6.stl"/>
      </geometry>
    </collision>
  </link>
  <link name="flange"/>
  <joint name="joint1" type="revolute">
    <origin rpy="1.5708 0 1.5708" xyz="0 0 0.10095"/>
    <parent link="base_link"/>
    <child link="link1"/>
    <axis xyz="0 1 0"/>
    <limit effort="0" lower="-6.2832" upper="6.2832" velocity="4.7124"/>
  </joint>
  <joint name="joint2" type="revolute">
    <origin rpy="3.1416 0 -1.5708" xyz="-0.06895 0.10315 0"/>
    <parent link="link1"/>
    <child link="link2"/>
    <axis xyz="0 -1 0"/>
    <limit effort="0" lower="-6.2832" upper="6.2832" velocity="4.7124"/>
  </joint>
  <joint name="joint3" type="revolute">
    <origin rpy="3.1416 -1.5708 0" xyz="-0.43 0.01 0"/>
    <parent link="link2"/>
    <child link="link3"/>
    <axis xyz="0 1 0"/>
    <limit effort="0" lower="-4.0492" upper="1.2566" velocity="7.1558"/>
  </joint>
  <joint name="joint4" type="revolute">
    <origin rpy="3.1416 1.5708 0" xyz="-0.41 -0.0117 0"/>
    <parent link="link3"/>
    <child link="link4"/>
    <axis xyz="0 -1 0"/>
    <limit effort="16.9" lower="-6.2832" upper="6.2832" velocity="8.2903"/>
  </joint>
  <joint name="joint5" type="revolute">
    <origin rpy="-1.5708 -1.5708 0" xyz="0.07565 0.0634 0"/>
    <parent link="link4"/>
    <child link="link5"/>
    <axis xyz="0 1 0"/>
    <limit effort="18.9" lower="-6.2832" upper="6.2832" velocity="8.2903"/>
  </joint>
  <joint name="joint6" type="revolute">
    <origin rpy="-1.5708 -1.5708 0" xyz="0.08085 0.0634 0"/>
    <parent link="link5"/>
    <child link="link6"/>
    <axis xyz="0 -1 0"/>
    <limit effort="10.2" lower="-6.2832" upper="6.2832" velocity="13.177"/>
  </joint>
  <joint name="jointf" type="fixed">
    <origin rpy="0 -1.5708 -1.5708" xyz="0 0.0734 0"/>
    <parent link="link6"/>
    <child link="flange"/>
  </joint>
  <!-- ========================================= -->
</robot>
