<?xml version="1.0" encoding="utf-8"?>
<robot
  name="rs_m90e7_description">
  <link
    name="base_link">
    <inertial>
      <origin
        xyz="0.00004 0.01193 0.05418"
        rpy="0 0 0" />
      <mass
        value="0.91957" />
      <inertia
        ixx=" 0.003109"
        ixy="-0.000002"
        ixz="-0.000001"
        iyy=" 0.002643"
        iyz="-0.000092"
        izz=" 0.003424" />
    </inertial>
    <visual>
      <origin
        xyz="0 0 0"
        rpy="0 0 0" />
      <geometry>
        <mesh
          filename="package://rs_m90e7_description/meshes/base_link.dae" />
      </geometry>
      <material
        name="">
        <color
          rgba="0 0 0 1" />
      </material>
    </visual>
    <collision>
      <origin
        xyz="0 0 0"
        rpy="0 0 0" />
      <geometry>
        <mesh
          filename="package://rs_m90e7_description/meshes/base_link.stl" />
      </geometry>
    </collision>
  </link>
  <link
    name="link1">
    <inertial>
      <origin
        xyz="-0.009177 0.089530 0.000000"
        rpy="0 0 0" />
      <mass
        value="2.095055" />
      <inertia
        ixx=" 0.006074"
        ixy="-0.000305"
        ixz=" 0.000000"
        iyy=" 0.004584"
        iyz=" 0.000000"
        izz=" 0.006717" />  
    </inertial>
    <visual>
      <origin
        xyz="0 0 0"
        rpy="0 0 0" />
      <geometry>
        <mesh
          filename="package://rs_m90e7_description/meshes/link1.dae" />
      </geometry>
      <material
        name="">
        <color
          rgba="0 0 0 1" />
      </material>
    </visual>
    <collision>
      <origin
        xyz="0 0 0"
        rpy="0 0 0" />
      <geometry>
        <mesh
          filename="package://rs_m90e7_description/meshes/link1.stl" />
      </geometry>
    </collision>
  </link>
  <joint
    name="joint1"
    type="revolute">
    <origin
      xyz="0 0 0.10095"
      rpy="1.5708 0 1.5708" />
    <parent
      link="base_link" />
    <child
      link="link1" />
    <axis
      xyz="0 1 0" />
    <limit
      lower="-6.2832"
      upper="6.2832"
      effort="0"
      velocity="4.7124" />
  </joint>
  <link
    name="link2">
    <inertial>
      <origin
        xyz="-0.21500 0.09444 0.00000"
        rpy="0 0 0" />
      <mass
        value="6.55317" />
      <inertia
        ixx=" 0.015891"
        ixy=" 0.000000"
        ixz=" 0.000000"
        iyy=" 0.206360"
        iyz=" 0.000000"
        izz=" 0.210906" />
    </inertial>
    <visual>
      <origin
        xyz="0 0 0"
        rpy="0 0 0" />
      <geometry>
        <mesh
          filename="package://rs_m90e7_description/meshes/link2.dae" />
      </geometry>
      <material
        name="">
        <color
          rgba="0 0 0 1" />
      </material>
    </visual>
    <collision>
      <origin
        xyz="0 0 0"
        rpy="0 0 0" />
      <geometry>
        <mesh
          filename="package://rs_m90e7_description/meshes/link2.stl" />
      </geometry>
    </collision>
  </link>
  <joint
    name="joint2"
    type="revolute">
    <origin
      xyz="-0.06895 0.10315 0"
      rpy="3.1416 0 -1.5708" />
    <parent
      link="link1" />
    <child
      link="link2" />
    <axis
      xyz="0 -1 0" />
    <limit
      lower="-6.2832"
      upper="6.2832"
      effort="0"
      velocity="4.7124" />
  </joint>
  <link
    name="link3">
    <inertial>
      <origin
        xyz="-0.19905 0.05265 0.00000"
        rpy="0 0 0" />
      <mass
        value="2.72253" />
      <inertia
        ixx=" 0.003560"
        ixy=" -0.000889"
        ixz=" 0.000000"
        iyy=" 0.080167"
        iyz=" 0.000000"
        izz=" 0.081015" />
    </inertial>
    <visual>
      <origin
        xyz="0 0 0"
        rpy="0 0 0" />
      <geometry>
        <mesh
          filename="package://rs_m90e7_description/meshes/link3.dae" />
      </geometry>
      <material
        name="">
        <color
          rgba="0 0 0 1" />
      </material>
    </visual>
    <collision>
      <origin
        xyz="0 0 0"
        rpy="0 0 0" />
      <geometry>
        <mesh
          filename="package://rs_m90e7_description/meshes/link3.stl" />
      </geometry>
    </collision>
  </link>
  <joint
    name="joint3"
    type="revolute">
    <origin
      xyz="-0.43 0 0"
      rpy="3.1416 -1.5708 0" />
    <parent
      link="link2" />
    <child
      link="link3" />
    <axis
      xyz="0 1 0" />
    <limit
      lower="-4.0492"
      upper="1.2566"
      effort="0"
      velocity="7.1558" />
  </joint>
  <link
    name="link4">
    <inertial>
      <origin
        xyz="0.015396 0.057512 0.000000"
        rpy="0 0 0" />
      <mass
        value="0.832958" />
      <inertia
        ixx=" 0.000897"
        ixy=" 0.000092"
        ixz=" 0.000000"
        iyy=" 0.001490"
        iyz=" 0.000000"
        izz=" 0.001595" />
    </inertial>
    <visual>
      <origin
        xyz="0 0 0"
        rpy="0 0 0" />
      <geometry>
        <mesh
          filename="package://rs_m90e7_description/meshes/link4.dae" />
      </geometry>
      <material
        name="">
        <color
          rgba="0 0 0 1" />
      </material>
    </visual>
    <collision>
      <origin
        xyz="0 0 0"
        rpy="0 0 0" />
      <geometry>
        <mesh
          filename="package://rs_m90e7_description/meshes/link4.stl" />
      </geometry>
    </collision>
  </link>
  <joint
    name="joint4"
    type="revolute">
    <origin
      xyz="-0.41 -0.0217 0"
      rpy="3.1416 1.5708 0" />
    <parent
      link="link3" />
    <child
      link="link4" />
    <axis
      xyz="0 -1 0" />
    <limit
      lower="-6.2832"
      upper="6.2832"
      effort="16.9"
      velocity="8.2903" />
  </joint>
  <link
    name="link5">
    <inertial>
      <origin
        xyz="0.015396 0.057512 0.000000"
        rpy="0 0 0" />
      <mass
        value="0.832958" />
      <inertia
        ixx=" 0.000897"
        ixy=" 0.000092"
        ixz=" 0.000000"
        iyy=" 0.001490"
        iyz=" 0.000000"
        izz=" 0.001595" />
    </inertial>
    <visual>
      <origin
        xyz="0 0 0"
        rpy="0 0 0" />
      <geometry>
        <mesh
          filename="package://rs_m90e7_description/meshes/link5.dae" />
      </geometry>
      <material
        name="">
        <color
          rgba="0 0 0 1" />
      </material>
    </visual>
    <collision>
      <origin
        xyz="0 0 0"
        rpy="0 0 0" />
      <geometry>
        <mesh
          filename="package://rs_m90e7_description/meshes/link5.stl" />
      </geometry>
    </collision>
  </link>
  <joint
    name="joint5"
    type="revolute">
    <origin
      xyz="0.07565 0.0634 0"
      rpy="-1.5708 -1.5708 0" />
    <parent
      link="link4" />
    <child
      link="link5" />
    <axis
      xyz="0 1 0" />
    <limit
      lower="-6.2832"
      upper="6.2832"
      effort="18.9"
      velocity="8.2903" />
  </joint>
  <link
    name="link6">
    <inertial>
      <origin
        xyz="0.000045 -0.035542 0.000000"
        rpy="0 0 0" />
      <mass
        value="0.391580" />
      <inertia
        ixx=" 0.000327"
        ixy=" 0.000000"
        ixz=" 0.000000"
        iyy=" 0.000360"
        iyz=" 0.000000"
        izz=" 0.000326" />
    </inertial>
    <visual>
      <origin
        xyz="0 0 0"
        rpy="0 0 0" />
      <geometry>
        <mesh
          filename="package://rs_m90e7_description/meshes/link6.dae" />
      </geometry>
      <material
        name="">
        <color
          rgba="0 0 0 1" />
      </material>
    </visual>
    <collision>
      <origin
        xyz="0 0 0"
        rpy="0 0 0" />
      <geometry>
        <mesh
          filename="package://rs_m90e7_description/meshes/link6.stl" />
      </geometry>
    </collision>
  </link>
  <joint
    name="joint6"
    type="revolute">
    <origin
      xyz="0.08085 0.0634 0"
      rpy="1.5708 -1.5708 0" />
    <parent
      link="link5" />
    <child
      link="link6" />
    <axis
      xyz="0 1 0" />
    <limit
      lower="-6.2832"
      upper="6.2832"
      effort="10.2"
      velocity="13.177" />
  </joint>
  <link name="tool0"/>
  <joint
    name="jtool"
    type="fixed">
    <origin
      xyz="0 -0.0734 0"
      rpy="0 1.5708 -1.5708" />
    <parent
      link="link6" />
    <child
      link="tool0" />
  </joint>

</robot>