<?xml version="1.0" encoding="utf-8"?>
<robot
  name="rs_m90e7_description">
  <link
    name="base_link">
    <inertial>
      <origin
        xyz="-0.10083 0.44571 0.10064"
        rpy="0 0 0" />
      <mass
        value="14.348" />
      <inertia
        ixx="1.1958"
        ixy="0.065249"
        ixz="-0.0022916"
        iyy="0.54334"
        iyz="-0.34884"
        izz="0.83638" />
    </inertial>
    <visual>
      <origin
        xyz="0 0 0"
        rpy="0 0 0" />
      <geometry>
        <mesh
          filename="package://rs_m90e7_description/meshes/base_link.STL" />
      </geometry>
      <material
        name="">
        <color
          rgba="0.79216 0.81961 0.93333 1" />
      </material>
    </visual>
    <collision>
      <origin
        xyz="0 0 0"
        rpy="0 0 0" />
      <geometry>
        <mesh
          filename="package://rs_m90e7_description/meshes/base_link.STL" />
      </geometry>
    </collision>
  </link>
  <link
    name="link1">
    <inertial>
      <origin
        xyz="-0.100828740851782 0.344764306357991 0.100637842700082"
        rpy="0 0 0" />
      <mass
        value="14.3478185896065" />
      <inertia
        ixx="1.19580116428598"
        ixy="0.065248716032548"
        ixz="-0.00229155804674572"
        iyy="0.543340717434702"
        iyz="-0.348841942351221"
        izz="0.836377518308467" />
    </inertial>
    <visual>
      <origin
        xyz="0 0 0"
        rpy="0 0 0" />
      <geometry>
        <mesh
          filename="package://rs_m90e7_description/meshes/link1.STL" />
      </geometry>
      <material
        name="">
        <color
          rgba="0.792156862745098 0.819607843137255 0.933333333333333 1" />
      </material>
    </visual>
    <collision>
      <origin
        xyz="0 0 0"
        rpy="0 0 0" />
      <geometry>
        <mesh
          filename="package://rs_m90e7_description/meshes/link1.STL" />
      </geometry>
    </collision>
  </link>
  <joint
    name="j1"
    type="continuous">
    <origin
      xyz="0 0 0.10095"
      rpy="1.5708 0 0" />
    <parent
      link="base_link" />
    <child
      link="link1" />
    <axis
      xyz="0 1 0" />
  </joint>
  <link
    name="link2">
    <inertial>
      <origin
        xyz="-0.241614292774701 0.0318787408517825 -0.100637842700082"
        rpy="0 0 0" />
      <mass
        value="14.3478185896065" />
      <inertia
        ixx="0.543340717434702"
        ixy="0.0652487160325479"
        ixz="-0.348841942351221"
        iyy="1.19580116428598"
        iyz="-0.00229155804674576"
        izz="0.836377518308467" />
    </inertial>
    <visual>
      <origin
        xyz="0 0 0"
        rpy="0 0 0" />
      <geometry>
        <mesh
          filename="package://rs_m90e7_description/meshes/link2.STL" />
      </geometry>
      <material
        name="">
        <color
          rgba="0.792156862745098 0.819607843137255 0.933333333333333 1" />
      </material>
    </visual>
    <collision>
      <origin
        xyz="0 0 0"
        rpy="0 0 0" />
      <geometry>
        <mesh
          filename="package://rs_m90e7_description/meshes/link2.STL" />
      </geometry>
    </collision>
  </link>
  <joint
    name="j2"
    type="continuous">
    <origin
      xyz="-0.06895 0.10315 0"
      rpy="-3.1416 0 -1.5708" />
    <parent
      link="link1" />
    <child
      link="link2" />
    <axis
      xyz="0 -1 0" />
  </joint>
  <link
    name="link3">
    <inertial>
      <origin
        xyz="-0.100637842700082 -0.0318787408517825 0.188385707225299"
        rpy="0 0 0" />
      <mass
        value="14.3478185896065" />
      <inertia
        ixx="0.836377518308467"
        ixy="0.00229155804674574"
        ixz="-0.348841942351221"
        iyy="1.19580116428598"
        iyz="-0.0652487160325479"
        izz="0.543340717434702" />
    </inertial>
    <visual>
      <origin
        xyz="0 0 0"
        rpy="0 0 0" />
      <geometry>
        <mesh
          filename="package://rs_m90e7_description/meshes/link3.STL" />
      </geometry>
      <material
        name="">
        <color
          rgba="0.792156862745098 0.819607843137255 0.933333333333333 1" />
      </material>
    </visual>
    <collision>
      <origin
        xyz="0 0 0"
        rpy="0 0 0" />
      <geometry>
        <mesh
          filename="package://rs_m90e7_description/meshes/link3.STL" />
      </geometry>
    </collision>
  </link>
  <joint
    name="j3"
    type="continuous">
    <origin
      xyz="-0.43 0 0"
      rpy="3.1416 -1.5708 0" />
    <parent
      link="link2" />
    <child
      link="link3" />
    <axis
      xyz="0 1 0" />
  </joint>
  <link
    name="link4">
    <inertial>
      <origin
        xyz="-0.188385707225299 0.017928791610254 -0.309362157299917"
        rpy="0 0 0" />
      <mass
        value="14.3478185896065" />
      <inertia
        ixx="0.543340717434702"
        ixy="-0.065248716032548"
        ixz="-0.348841942351221"
        iyy="1.19580116428598"
        iyz="0.00229155804674572"
        izz="0.836377518308467" />
    </inertial>
    <visual>
      <origin
        xyz="0 0 0"
        rpy="0 0 0" />
      <geometry>
        <mesh
          filename="package://rs_m90e7_description/meshes/link4.STL" />
      </geometry>
      <material
        name="">
        <color
          rgba="0.792156862745098 0.819607843137255 0.933333333333333 1" />
      </material>
    </visual>
    <collision>
      <origin
        xyz="0 0 0"
        rpy="0 0 0" />
      <geometry>
        <mesh
          filename="package://rs_m90e7_description/meshes/link4.STL" />
      </geometry>
    </collision>
  </link>
  <joint
    name="j4"
    type="continuous">
    <origin
      xyz="-0.41 -0.01395 0"
      rpy="3.1416 1.5708 0" />
    <parent
      link="link3" />
    <child
      link="link4" />
    <axis
      xyz="0 -1 0" />
  </joint>
  <link
    name="link5">
    <inertial>
      <origin
        xyz="-0.30936 -0.25629 -0.045471"
        rpy="0 0 0" />
      <mass
        value="14.348" />
      <inertia
        ixx="0.83638"
        ixy="-0.34884"
        ixz="0.0022916"
        iyy="0.54334"
        iyz="-0.065249"
        izz="1.1958" />
    </inertial>
    <visual>
      <origin
        xyz="0 0 0"
        rpy="0 0 0" />
      <geometry>
        <mesh
          filename="package://rs_m90e7_description/meshes/link5.STL" />
      </geometry>
      <material
        name="">
        <color
          rgba="0.79216 0.81961 0.93333 1" />
      </material>
    </visual>
    <collision>
      <origin
        xyz="0 0 0"
        rpy="0 0 0" />
      <geometry>
        <mesh
          filename="package://rs_m90e7_description/meshes/link5.STL" />
      </geometry>
    </collision>
  </link>
  <joint
    name="j5"
    type="continuous">
    <origin
      xyz="0.0679 0.0634 0"
      rpy="-1.5708 -1.5708 0" />
    <parent
      link="link4" />
    <child
      link="link5" />
    <axis
      xyz="0 1 0" />
  </joint>
  <link
    name="tool">
    <inertial>
      <origin
        xyz="0.045471 -0.39021 0.31969"
        rpy="0 0 0" />
      <mass
        value="14.348" />
      <inertia
        ixx="1.1958"
        ixy="-0.0022916"
        ixz="-0.065249"
        iyy="0.83638"
        iyz="0.34884"
        izz="0.54334" />
    </inertial>
    <visual>
      <origin
        xyz="0 0 0"
        rpy="0 0 0" />
      <geometry>
        <mesh
          filename="package://rs_m90e7_description/meshes/tool.STL" />
      </geometry>
      <material
        name="">
        <color
          rgba="0.79216 0.81961 0.93333 1" />
      </material>
    </visual>
    <collision>
      <origin
        xyz="0 0 0"
        rpy="0 0 0" />
      <geometry>
        <mesh
          filename="package://rs_m90e7_description/meshes/tool.STL" />
      </geometry>
    </collision>
  </link>
  <joint
    name="j6"
    type="continuous">
    <origin
      xyz="0.08085 0.0634 0"
      rpy="-1.5708 1.5708 3.1416" />
    <parent
      link="link5" />
    <child
      link="tool" />
    <axis
      xyz="0 -1 0" />
  </joint>
</robot>